<mujoco model="model">
    <visual>
        <headlight ambient="0.5 0.5 0.5" />
    </visual>

    <option gravity="0 0 -9.81" />

    <worldbody>

        <body pos="0 0 0">
            <body pos="0.272 0 0.272" name ='D'>
                <joint name='D' type ='slide' axis='1 0 0'/>
                <geom name = 'D' type="box" size="0.05 0.01 0.015" rgba="0.1 0.2 1 0.5"/>
                <body pos="0 0 0" name = 'L2'>
                    <joint name='L2' type='hinge' axis='0 1 0' pos="0 0 0"/>
                    <geom name="L2" type="capsule" size=".001" fromto="0 0 0  -0.272 0 -0.204"/>   
                    <body pos="-0.272 0 -0.204" name = 'A'>
                        <joint/>

                        <geom name="A" type="sphere" size=".01" rgba="1 1 0.5 1"  />

                        <body pos="0 0 0" name = 'L1'>
                            <joint name='L1' type='hinge' range="-45 0" axis='0 1 0' pos="0 0 0"/>

                            <geom name="L1" type="capsule" size=".001" rgba="0.5 0.5 0.5 1" fromto="0 0 0  0 0 -0.075" />

                            <site name="O" pos="0 0 -0.075"/>
                        </body>  
                    </body>             

                    <body pos="-0.15 0 -0.11" name = 'B'>
                        <joint/>

                        <geom name="B" type="sphere" size=".01" rgba="1 1 0.2 1" />

                        <body pos="0 0 0" name = 'L3'>
                            <joint name='L3' type='hinge' axis='0 1 0' pos="0 0 0"/>

                            <geom name="L3" type="capsule" size=".001" rgba="0.5 0.5 0.5 1" fromto="0 0 0  0 0 -0.1875" />
                            
                            <site name="C" pos="0 0 -0.1875"/>
                        </body>                          
                    </body>          
                </body>

            </body>

        </body>


        <site name="O_fix" pos="0 0 0"/>

        <site name="C_fix" pos="0.15 0 0"/>

    </worldbody>

    <actuator>
        <position name="D_actuator" joint="D" />
    </actuator>

    <equality>
        <connect site1="O_fix" site2="O"/>
        <connect site1="C_fix" site2="C"/>
    </equality>

</mujoco>